<mujoco model="brazorobotico">
  <compiler angle="radian" meshdir="https://raw.githubusercontent.com/jaso529/Tarea-3-Cinem-tica-Grupo-10/main/modelos/" autolimits="true"/>

  <option gravity="0 0 -9.81" />

  <default>
    <default class="brazo">
      <geom friction="0.9" solimp="0.95 0.99 0.001" solref="0.004 1" margin="0.001"/>
      <joint type="hinge" damping="0.5" armature="0.01" limited="true"/>
      <position kp="10" forcerange="-100 100"/>
    </default>
  </default>

  <asset>
    <material name="gris" specular="0.5" shininess="0.25" rgba="0.6 0.6 0.6 1"/>
    <material name="azul" specular="0.5" shininess="0.25" rgba="0.2 0.5 0.8 1"/>
    <material name="verde" specular="0.5" shininess="0.25" rgba="0.3 0.6 0.3 1"/>
    <material name="naranja" specular="0.5" shininess="0.25" rgba="0.9 0.4 0.1 1"/>

    <mesh file="base.obj"/>
    <mesh file="cintura.obj"/>
    <mesh file="hombro.obj"/>
    <mesh file="codo.obj"/>
    <mesh file="muneca.obj"/>
    <mesh file="gripper.obj"/>
    </asset>

  <worldbody>
    <light name="spotlight" mode="targetbodycom" target="codo" pos="0 -1 2"/>


    <body name="base" pos="0 0 0" childclass="brazo">
      <inertial mass="1.5" pos="0 0 0.05" diaginertia="0.01 0.01 0.02"/>
      <joint name="j_base_z" axis="0 0 1" range="-3.14 3.14"/>
      <geom type="mesh" mesh="base" material="naranja" group="1"/>

      <body name="cintura" pos="0 0 0.106">
        <inertial mass="1.0" pos="0 0 0.045" diaginertia="0.008 0.008 0.01"/>
        <joint name="j_cintura_y" axis="0 1 0" range="-1.57 1.57"/>
        <geom type="mesh" mesh="cintura" material="naranja" group="1"/>

        <body name="hombro" pos="0 0 0.094">
            <inertial mass="2.5" pos="0 0 0.17" diaginertia="0.05 0.05 0.01"/>
            <joint name="j_hombro_y" axis="0 1 0" range="-1.57 1.57"/>
            <geom type="mesh" mesh="hombro" material="verde" group="1"/>

            <body name="codo" pos="0 0 0.344">
                <inertial mass="2.0" pos="0 0 0.175" diaginertia="0.04 0.04 0.008"/>
                <joint name="j_codo_z" axis="0 0 1" range="-3.14 3.14"/>
                <geom type="mesh" mesh="codo" material="azul" group="1"/>

                <body name="muneca" pos="0 0 0.350">
                    <inertial mass="0.5" pos="0 0 0.05" diaginertia="0.002 0.002 0.001"/>
                    <joint name="j_muneca_y" axis="0 1 0" range="-1.57 1.57"/>
                    <geom type="mesh" mesh="muneca" group="1"/>

                    <body name="gripper" pos="0 0 0.100">
                        <inertial mass="0.3" pos="0 0 0.025" diaginertia="0.001 0.001 0.0005"/>
                        <joint name="j_gripper_z" axis="0 0 1" range="-3.14 3.14"/>
                        <geom type="mesh" mesh="gripper" material="gris" group="1"/>
                        <site name="end_effector" pos="0 0 0.05" size="0.01"/>
                    </body>
                </body>
            </body>
        </body>
      </body>
    </body>
  </worldbody>

  <actuator>
    <position name="act_base_z"    joint="j_base_z"    ctrlrange="-3.14 3.14"/>
    <position name="act_cintura_y" joint="j_cintura_y" ctrlrange="-1.57 1.57"/>
    <position name="act_hombro_y"  joint="j_hombro_y"  ctrlrange="-1.57 1.57"/>
    <position name="act_codo_z"    joint="j_codo_z"    ctrlrange="-3.14 3.14"/>
    <position name="act_muneca_y"  joint="j_muneca_y"  ctrlrange="-1.57 1.57"/>
    <position name="act_gripper_z" joint="j_gripper_z" ctrlrange="-3.14 3.14"/>
  </actuator>

  <keyframe>
      <key name="home" qpos="0 0 0 0 0 0"/>
  </keyframe>

</mujoco>
